now service sends Promise 1 resolve -1 reject

 Task;
  1. catch error in component
  2. throw error in then and handle it
  3. make async method with get promise and catch errir
    getDataAsync in c11 component


  async getDataAsync(): Promise<void> {
    try{
      const data = await this.c11Service.getPromise(-1);
      console.log('inside try block', data);
    } catch(error) {
      console.error('Inside catch in getDataAsync', error)
    }
  }

  4. implement 2 ways to catch errors
